2025-03-17 20:54:21,132 INFO    MainThread:25716 [wandb_init.py:setup_run_log_directory():647] Logging user logs to C:\Users\pankaj\Desktop\dl\DA6401_Assignment1\final_DL\wandb\run-20250317_205421-vvk8hbda\logs\debug.log
2025-03-17 20:54:21,133 INFO    MainThread:25716 [wandb_init.py:setup_run_log_directory():648] Logging internal logs to C:\Users\pankaj\Desktop\dl\DA6401_Assignment1\final_DL\wandb\run-20250317_205421-vvk8hbda\logs\debug-internal.log
2025-03-17 20:54:21,133 INFO    MainThread:25716 [wandb_init.py:init():761] calling init triggers
2025-03-17 20:54:21,134 INFO    MainThread:25716 [wandb_init.py:init():766] wandb.init called with sweep_config: {}
config: {'_wandb': {}}
2025-03-17 20:54:21,134 INFO    MainThread:25716 [wandb_init.py:init():784] starting backend
2025-03-17 20:54:21,134 INFO    MainThread:25716 [wandb_init.py:init():788] sending inform_init request
2025-03-17 20:54:21,141 INFO    MainThread:25716 [backend.py:_multiprocessing_setup():101] multiprocessing start_methods=spawn, using: spawn
2025-03-17 20:54:21,141 INFO    MainThread:25716 [wandb_init.py:init():798] backend started and connected
2025-03-17 20:54:21,224 INFO    MainThread:25716 [wandb_init.py:init():891] updated telemetry
2025-03-17 20:54:21,334 INFO    MainThread:25716 [wandb_init.py:init():915] communicating run to backend with 90.0 second timeout
2025-03-17 20:54:22,723 ERROR   MainThread:25716 [wandb_init.py:init():1478] error in wandb.init()
Traceback (most recent call last):
  File "C:\Users\pankaj\anaconda3\envs\Myenv\Lib\site-packages\wandb\sdk\wandb_init.py", line 1468, in init
    return wi.init(run_settings, run_config)
           ^^^^^^^^^^^^^^^^^^^^^^^^^^^^^^^^^
  File "C:\Users\pankaj\anaconda3\envs\Myenv\Lib\site-packages\wandb\sdk\wandb_init.py", line 963, in init
    raise error
wandb.errors.errors.CommError: failed to upsert bucket: returned error 403: {"data":{"upsertBucket":null},"errors":[{"message":"permission denied","path":["upsertBucket"],"extensions":{"code":"PERMISSION_ERROR"}}]}
2025-03-17 20:54:23,727 INFO    MsgRouterThr:25716 [mailbox.py:close():129] Closing mailbox, abandoning 1 handles.
