Traceback (most recent call last):
  File "C:\Users\pankaj\Desktop\dl\DA6401_Assignment1\final_DL\Q1.py", line 52, in <module>
    wandb.Image(img, caption=class_names[class_idx]),
    ^^^^^^^^^^^^^^^^^^^^^^^^^^^^^^^^^^^^^^^^^^^^^^^^
  File "C:\Users\pankaj\anaconda3\envs\Myenv\Lib\site-packages\wandb\sdk\data_types\image.py", line 179, in __init__
    self._initialize_from_data(data_or_path, mode, file_type)
  File "C:\Users\pankaj\anaconda3\envs\Myenv\Lib\site-packages\wandb\sdk\data_types\image.py", line 324, in _initialize_from_data
    self.to_uint8(data), mode=mode or self.guess_mode(data)
                                      ^^^^^^^^^^^^^^^^^^^^^
  File "C:\Users\pankaj\anaconda3\envs\Myenv\Lib\site-packages\wandb\sdk\data_types\image.py", line 484, in guess_mode
    raise ValueError(
ValueError: Un-supported shape for image conversion [60000]
